<?xml version="1.0" ?>
<!-- =================================================================================== -->
<!-- |    This document was autogenerated by xacro from cugo.xacro                     | -->
<!-- |    EDITING THIS FILE BY HAND IS NOT RECOMMENDED                                 | -->
<!-- =================================================================================== -->
<robot name="cugo_v3">
  <material name="white">
    <color rgba="1.0 1.0 1.0 1.0"/>
  </material>
  <material name="red">
    <color rgba="1.0 0.0 0.0 1.0"/>
  </material>
  <material name="green">
    <color rgba="0.0 1.0 0.0 1.0"/>
  </material>
  <material name="blue">
    <color rgba="0.0 0.0 1.0 1.0"/>
  </material>
  <material name="yellow">
    <color rgba="1.0 1.0 0.0 1.0"/>
  </material>
  <material name="cyan">
    <color rgba="0.0 1.0 1.0 1.0"/>
  </material>
  <material name="purple">
    <color rgba="1.0 0.0 1.0 1.0"/>
  </material>
  <material name="black">
    <color rgba="0.0 0.0 0.0 1.0"/>
  </material>
  <material name="dark">
    <color rgba="0.3 0.3 0.3 1.0"/>
  </material>
  <material name="dummy_white">
    <color rgba="1.0 1.0 1.0 0.0"/>
  </material>
  <link name="base_footprint"/>
  <joint name="base_footprint_joint" type="fixed">
    <parent link="base_footprint"/>
    <child link="base_link"/>
    <origin rpy="0 0 0" xyz="0.0 0.0 0.1065"/>
  </joint>
  <link name="base_link"/>
  <joint name="body_joint" type="fixed">
    <parent link="base_link"/>
    <child link="base_body"/>
    <origin rpy="0 0 0" xyz="0 0 0"/>
  </joint>
  <link name="base_body">
    <visual>
      <geometry>
        <mesh filename="file:///home/emu/ros2_ws/install/cugo_ros2_control/share/cugo_ros2_control/models/cugo/meshes/roskit-Compound.dae" scale="1 1 1"/>
      </geometry>
      <origin rpy="0 0 -1.57" xyz="0 0 0"/>
      <material name="red"/>
    </visual>
    <inertial>
      <mass value="0.1"/>
      <inertia ixx="0.13542" ixy="0.0" ixz="0.0" iyy="0.10833" iyz="0.0" izz="0.17708"/>
    </inertial>
  </link>
  <joint name="body_collision_joint" type="fixed">
    <parent link="base_body"/>
    <child link="body_collision"/>
    <origin rpy="0 0 0" xyz="0 0 0.18"/>
  </joint>
  <link name="body_collision">
    <visual>
      <geometry>
        <box size="0.42 0.58 0.2"/>
      </geometry>
      <origin rpy="0 0 0" xyz="0 0 0"/>
      <material name="dummy_white"/>
    </visual>
    <collision>
      <geometry>
        <box size="0.42 0.58 0.2"/>
      </geometry>
    </collision>
    <inertial>
      <mass value="0.1"/>
      <inertia ixx="0.13542" ixy="0.0" ixz="0.0" iyy="0.10833" iyz="0.0" izz="0.17708"/>
    </inertial>
  </link>
  <joint name="left_wheel_joint" type="continuous">
    <axis rpy="0 0 0" xyz="0 0 -1"/>
    <limit effort="0.5" lower="-1.57" upper="1.57" velocity="2.0"/>
    <parent link="base_body"/>
    <child link="left_wheel"/>
    <origin rpy="0 1.57075 -1.57" xyz="0 0.24 -0.105"/>
  </joint>
  <link name="left_wheel">
    <visual>
      <origin rpy="0 0 0" xyz="0 0 0"/>
      <geometry>
        <cylinder length="0.06" radius="0.03858"/>
      </geometry>
      <material name="dummy_white"/>
    </visual>
    <collision>
      <geometry>
        <cylinder length="0.145" radius="0.03858"/>
      </geometry>
    </collision>
    <inertial>
      <mass value="0.1"/>
      <inertia ixx="0.00024" ixy="0.0" ixz="0.0" iyy="0.00024" iyz="0.0" izz="0.00015"/>
    </inertial>
  </link>
  <joint name="left_wheel_joint_center_mini_front" type="continuous">
    <axis rpy="0 0 0" xyz="0 0 -1"/>
    <limit effort="1.0" lower="-1.57" upper="1.57" velocity="2.0"/>
    <parent link="base_body"/>
    <child link="left_wheel_center_mini_front"/>
    <origin rpy="0 1.57075 -1.57" xyz="0.07716 0.24 -0.105"/>
  </joint>
  <link name="left_wheel_center_mini_front">
    <visual>
      <origin rpy="0 0 0" xyz="0 0 0"/>
      <geometry>
        <cylinder length="0.06" radius="0.03858"/>
      </geometry>
      <material name="dummy_white"/>
    </visual>
    <collision>
      <geometry>
        <cylinder length="0.145" radius="0.03858"/>
      </geometry>
    </collision>
    <inertial>
      <mass value="0.1"/>
      <inertia ixx="0.00024" ixy="0.0" ixz="0.0" iyy="0.00024" iyz="0.0" izz="0.00015"/>
    </inertial>
  </link>
  <joint name="left_wheel_joint_center_mini_back" type="continuous">
    <axis rpy="0 0 0" xyz="0 0 -1"/>
    <limit effort="1.0" lower="-1.57" upper="1.57" velocity="2.0"/>
    <parent link="base_body"/>
    <child link="left_wheel_center_mini_back"/>
    <origin rpy="0 1.57075 -1.57" xyz="-0.07716 0.24 -0.105"/>
  </joint>
  <link name="left_wheel_center_mini_back">
    <visual>
      <origin rpy="0 0 0" xyz="0 0 0"/>
      <geometry>
        <cylinder length="0.06" radius="0.03858"/>
      </geometry>
      <material name="dummy_white"/>
    </visual>
    <collision>
      <geometry>
        <cylinder length="0.145" radius="0.03858"/>
      </geometry>
    </collision>
    <inertial>
      <mass value="0.1"/>
      <inertia ixx="0.00024" ixy="0.0" ixz="0.0" iyy="0.00024" iyz="0.0" izz="0.00015"/>
    </inertial>
  </link>
  <joint name="left_wheel_joint_big_front" type="continuous">
    <axis rpy="0 0 0" xyz="0 0 -1"/>
    <limit effort="1.0" lower="-1.57" upper="1.57" velocity="2.0"/>
    <parent link="base_body"/>
    <child link="left_wheel_big_front"/>
    <origin rpy="0 1.57075 -1.57" xyz="0.172 0.24 -0.08"/>
  </joint>
  <link name="left_wheel_big_front">
    <visual>
      <origin rpy="0 0 0" xyz="0 0 0"/>
      <geometry>
        <cylinder length="0.06" radius="0.03858"/>
      </geometry>
      <material name="dummy_white"/>
    </visual>
    <collision>
      <geometry>
        <cylinder length="0.145" radius="0.03858"/>
      </geometry>
    </collision>
    <inertial>
      <mass value="0.1"/>
      <inertia ixx="0.00024" ixy="0.0" ixz="0.0" iyy="0.00024" iyz="0.0" izz="0.00015"/>
    </inertial>
  </link>
  <joint name="left_wheel_joint_big_back" type="continuous">
    <axis rpy="0 0 0" xyz="0 0 -1"/>
    <limit effort="1.0" lower="-1.57" upper="1.57" velocity="2.0"/>
    <parent link="base_body"/>
    <child link="left_wheel_big_back"/>
    <origin rpy="0 1.57075 -1.57" xyz="-0.172 0.24 -0.08"/>
  </joint>
  <link name="left_wheel_big_back">
    <visual>
      <origin rpy="0 0 0" xyz="0 0 0"/>
      <geometry>
        <cylinder length="0.06" radius="0.03858"/>
      </geometry>
      <material name="dummy_white"/>
    </visual>
    <collision>
      <geometry>
        <cylinder length="0.145" radius="0.03858"/>
      </geometry>
    </collision>
    <inertial>
      <mass value="0.1"/>
      <inertia ixx="0.00024" ixy="0.0" ixz="0.0" iyy="0.00024" iyz="0.0" izz="0.00015"/>
    </inertial>
  </link>
  <joint name="right_wheel_joint" type="continuous">
    <axis rpy="0 0 0" xyz="0 0 -1"/>
    <limit effort="1.0" lower="-1.57" upper="1.57" velocity="2.0"/>
    <parent link="base_body"/>
    <child link="right_wheel"/>
    <origin rpy="0 1.57075 -1.57" xyz="0 -0.22 -0.105"/>
  </joint>
  <link name="right_wheel">
    <visual>
      <origin rpy="0 0 0" xyz="0 0 0"/>
      <geometry>
        <cylinder length="0.06" radius="0.03858"/>
      </geometry>
      <material name="dummy_white"/>
    </visual>
    <collision>
      <geometry>
        <cylinder length="0.145" radius="0.03858"/>
      </geometry>
    </collision>
    <inertial>
      <mass value="0.1"/>
      <inertia ixx="0.00024" ixy="0.0" ixz="0.0" iyy="0.00024" iyz="0.0" izz="0.00015"/>
    </inertial>
  </link>
  <joint name="right_wheel_joint_center_mini_front" type="continuous">
    <axis rpy="0 0 0" xyz="0 0 -1"/>
    <limit effort="1.0" lower="-1.57" upper="1.57" velocity="2.0"/>
    <parent link="base_body"/>
    <child link="right_wheel_center_mini_front"/>
    <origin rpy="0 1.57075 -1.57" xyz="0.07716 -0.22 -0.105"/>
  </joint>
  <link name="right_wheel_center_mini_front">
    <visual>
      <origin rpy="0 0 0" xyz="0 0 0"/>
      <geometry>
        <cylinder length="0.06" radius="0.03858"/>
      </geometry>
      <material name="dummy_white"/>
    </visual>
    <collision>
      <geometry>
        <cylinder length="0.145" radius="0.03858"/>
      </geometry>
    </collision>
    <inertial>
      <mass value="0.1"/>
      <inertia ixx="0.00024" ixy="0.0" ixz="0.0" iyy="0.00024" iyz="0.0" izz="0.00015"/>
    </inertial>
  </link>
  <joint name="right_wheel_joint_center_mini_back" type="continuous">
    <axis rpy="0 0 0" xyz="0 0 -1"/>
    <limit effort="1.0" lower="-1.57" upper="1.57" velocity="2.0"/>
    <parent link="base_body"/>
    <child link="right_wheel_center_mini_back"/>
    <origin rpy="0 1.57075 -1.57" xyz="-0.07716 -0.22 -0.105"/>
  </joint>
  <link name="right_wheel_center_mini_back">
    <visual>
      <origin rpy="0 0 0" xyz="0 0 0"/>
      <geometry>
        <cylinder length="0.06" radius="0.03858"/>
      </geometry>
      <material name="dummy_white"/>
    </visual>
    <collision>
      <geometry>
        <cylinder length="0.145" radius="0.03858"/>
      </geometry>
    </collision>
    <inertial>
      <mass value="0.1"/>
      <inertia ixx="0.00024" ixy="0.0" ixz="0.0" iyy="0.00024" iyz="0.0" izz="0.00015"/>
    </inertial>
  </link>
  <joint name="right_wheel_joint_big_front" type="continuous">
    <axis rpy="0 0 0" xyz="0 0 -1"/>
    <limit effort="1.0" lower="-1.57" upper="1.57" velocity="2.0"/>
    <parent link="base_body"/>
    <child link="right_wheel_big_front"/>
    <origin rpy="0 1.57075 -1.57" xyz="0.172 -0.22 -0.08"/>
  </joint>
  <link name="right_wheel_big_front">
    <visual>
      <origin rpy="0 0 0" xyz="0 0 0"/>
      <geometry>
        <cylinder length="0.06" radius="0.03858"/>
      </geometry>
      <material name="dummy_white"/>
    </visual>
    <collision>
      <geometry>
        <cylinder length="0.145" radius="0.03858"/>
      </geometry>
    </collision>
    <inertial>
      <mass value="0.1"/>
      <inertia ixx="0.00024" ixy="0.0" ixz="0.0" iyy="0.00024" iyz="0.0" izz="0.00015"/>
    </inertial>
  </link>
  <joint name="right_wheel_joint_big_back" type="continuous">
    <axis rpy="0 0 0" xyz="0 0 -1"/>
    <limit effort="1.0" lower="-1.57" upper="1.57" velocity="2.0"/>
    <parent link="base_body"/>
    <child link="right_wheel_big_back"/>
    <origin rpy="0 1.57075 -1.57" xyz="-0.172 -0.22 -0.08"/>
  </joint>
  <link name="right_wheel_big_back">
    <visual>
      <origin rpy="0 0 0" xyz="0 0 0"/>
      <geometry>
        <cylinder length="0.06" radius="0.03858"/>
      </geometry>
      <material name="dummy_white"/>
    </visual>
    <collision>
      <geometry>
        <cylinder length="0.145" radius="0.03858"/>
      </geometry>
    </collision>
    <inertial>
      <mass value="0.1"/>
      <inertia ixx="0.00024" ixy="0.0" ixz="0.0" iyy="0.00024" iyz="0.0" izz="0.00015"/>
    </inertial>
  </link>
  <joint name="left_crawler_joint" type="fixed">
    <axis rpy="0 0 0" xyz="0 0 -1"/>
    <parent link="base_body"/>
    <child link="left_crawler"/>
    <origin rpy="0 1.57075 -1.57" xyz="-0.01 0.22 -0.043"/>
  </joint>
  <link name="left_crawler">
    <visual>
      <origin rpy="0 0 0" xyz="0 0 0"/>
      <geometry>
        <mesh filename="file:///home/emu/ros2_ws/install/cugo_ros2_control/share/cugo_ros2_control/models/cugo/meshes/cugo_v3_l-CuGoV3_L001.stl" scale="0.001 0.001 0.001"/>
      </geometry>
      <material name="white"/>
    </visual>
    <inertial>
      <mass value="0.1"/>
      <inertia ixx="0.00024" ixy="0.0" ixz="0.0" iyy="0.00024" iyz="0.0" izz="0.00015"/>
    </inertial>
  </link>
  <joint name="right_crawler_joint" type="fixed">
    <axis rpy="0 0 0" xyz="0 0 -1"/>
    <parent link="base_body"/>
    <child link="right_crawler"/>
    <origin rpy="0 1.57075 -1.57" xyz="-0.10 -0.2065 -0.055"/>
  </joint>
  <link name="right_crawler">
    <visual>
      <origin rpy="0 0 0" xyz="0 0 0"/>
      <geometry>
        <mesh filename="file:///home/emu/ros2_ws/install/cugo_ros2_control/share/cugo_ros2_control/models/cugo/meshes/cugo_v3_r-CuGoV3_R001.stl" scale="0.001 0.001 0.001"/>
      </geometry>
      <material name="white"/>
    </visual>
    <inertial>
      <mass value="0.1"/>
      <inertia ixx="0.00024" ixy="0.0" ixz="0.0" iyy="0.00024" iyz="0.0" izz="0.00015"/>
    </inertial>
  </link>
  <!--diff_drive_controller plugin-->
  <gazebo>
    <plugin filename="libgazebo_ros_diff_drive.so" name="cugo_diff_drive">
      <update_rate>10</update_rate>
      <!-- wheels -->
      <left_joint>left_wheel_joint</left_joint>
      <right_joint>right_wheel_joint</right_joint>
      <!-- kinematics -->
      <wheel_separation>0.460</wheel_separation>
      <wheel_diameter>0.07716</wheel_diameter>
      <!-- limits -->
      <max_wheel_acceleration>1.0</max_wheel_acceleration>
      <max_wheel_torque>5.0</max_wheel_torque>
      <command_topic>cmd_vel</command_topic>
      <!-- output -->
      <publish_odom>true</publish_odom>
      <publish_odom_tf>true</publish_odom_tf>
      <publish_wheel_tf>true</publish_wheel_tf>
      <!--<publish_wheel_joint_state>true</publish_wheel_joint_state>-->
      <odometry_topic>odom</odometry_topic>
      <odometry_frame>odom</odometry_frame>
      <robot_base_frame>base_footprint</robot_base_frame>
      <!--<robot_base_frame>base_link</robot_base_frame>-->
      <odometry_source>1</odometry_source>
      <!--<legacy_mode>false</legacy_mode>-->
    </plugin>
  </gazebo>
  <gazebo>
    <plugin filename="libgazebo_ros_diff_drive.so" name="cugo_diff_drive_mini_front">
      <update_rate>10</update_rate>
      <!-- wheels -->
      <left_joint>left_wheel_joint_center_mini_front</left_joint>
      <right_joint>right_wheel_joint_center_mini_front</right_joint>
      <!-- kinematics -->
      <wheel_separation>0.460</wheel_separation>
      <wheel_diameter>0.07716</wheel_diameter>
      <!-- limits -->
      <max_wheel_acceleration>1.0</max_wheel_acceleration>
      <max_wheel_torque>5.0</max_wheel_torque>
      <command_topic>cmd_vel</command_topic>
      <legacyMode>false</legacyMode>
    </plugin>
  </gazebo>
  <gazebo>
    <plugin filename="libgazebo_ros_diff_drive.so" name="cugo_diff_drive_mini_back">
      <update_rate>10</update_rate>
      <!-- wheels -->
      <left_joint>left_wheel_joint_center_mini_back</left_joint>
      <right_joint>right_wheel_joint_center_mini_back</right_joint>
      <!-- kinematics -->
      <wheel_separation>0.460</wheel_separation>
      <wheel_diameter>0.07716</wheel_diameter>
      <!-- limits -->
      <max_wheel_acceleration>1.0</max_wheel_acceleration>
      <max_wheel_torque>5.0</max_wheel_torque>
      <command_topic>cmd_vel</command_topic>
      <legacyMode>false</legacyMode>
    </plugin>
  </gazebo>
  <gazebo>
    <plugin filename="libgazebo_ros_diff_drive.so" name="cugo_diff_drive_big_front">
      <update_rate>10</update_rate>
      <!-- wheels -->
      <left_joint>left_wheel_joint_big_front</left_joint>
      <right_joint>right_wheel_joint_big_front</right_joint>
      <!-- kinematics -->
      <wheel_separation>0.460</wheel_separation>
      <wheel_diameter>0.07716</wheel_diameter>
      <!-- limits -->
      <max_wheel_acceleration>1.0</max_wheel_acceleration>
      <max_wheel_torque>5.0</max_wheel_torque>
      <command_topic>cmd_vel</command_topic>
      <legacyMode>false</legacyMode>
    </plugin>
  </gazebo>
  <gazebo>
    <plugin filename="libgazebo_ros_diff_drive.so" name="cugo_diff_drive_big_back">
      <update_rate>10</update_rate>
      <!-- wheels -->
      <left_joint>left_wheel_joint_big_back</left_joint>
      <right_joint>right_wheel_joint_big_back</right_joint>
      <!-- kinematics -->
      <wheel_separation>0.460</wheel_separation>
      <wheel_diameter>0.07716</wheel_diameter>
      <!-- limits -->
      <max_wheel_acceleration>1.0</max_wheel_acceleration>
      <max_wheel_torque>5.0</max_wheel_torque>
      <command_topic>cmd_vel</command_topic>
      <legacyMode>false</legacyMode>
    </plugin>
  </gazebo>
  <gazebo reference="right_wheel">
    <mu1>2.0</mu1>
    <mu2>2.0</mu2>
    <material>Gazebo/GreyTransparent</material>
  </gazebo>
  <gazebo reference="right_wheel_center_mini_front">
    <mu1>2.0</mu1>
    <mu2>2.0</mu2>
    <material>Gazebo/GreyTransparent</material>
  </gazebo>
  <gazebo reference="right_wheel_center_mini_back">
    <mu1>2.0</mu1>
    <mu2>2.0</mu2>
    <material>Gazebo/GreyTransparent</material>
  </gazebo>
  <gazebo reference="right_wheel_mini_front">
    <mu1>2.0</mu1>
    <mu2>2.0</mu2>
    <material>Gazebo/GreyTransparent</material>
  </gazebo>
  <gazebo reference="right_wheel_mini_back">
    <mu1>2.0</mu1>
    <mu2>2.0</mu2>
    <material>Gazebo/GreyTransparent</material>
  </gazebo>
  <gazebo reference="right_wheel_big_front">
    <mu1>2.0</mu1>
    <mu2>2.0</mu2>
    <material>Gazebo/GreyTransparent</material>
  </gazebo>
  <gazebo reference="right_wheel_big_back">
    <mu1>2.0</mu1>
    <mu2>2.0</mu2>
    <material>Gazebo/GreyTransparent</material>
  </gazebo>
  <gazebo reference="left_wheel">
    <mu1>2.0</mu1>
    <mu2>2.0</mu2>
    <material>Gazebo/GreyTransparent</material>
  </gazebo>
  <gazebo reference="left_wheel_center_mini_front">
    <mu1>2.0</mu1>
    <mu2>2.0</mu2>
    <material>Gazebo/GreyTransparent</material>
  </gazebo>
  <gazebo reference="left_wheel_center_mini_back">
    <mu1>2.0</mu1>
    <mu2>2.0</mu2>
    <material>Gazebo/GreyTransparent</material>
  </gazebo>
  <gazebo reference="left_wheel_mini_front">
    <mu1>2.0</mu1>
    <mu2>2.0</mu2>
    <material>Gazebo/GreyTransparent</material>
  </gazebo>
  <gazebo reference="left_wheel_mini_back">
    <mu1>2.0</mu1>
    <mu2>2.0</mu2>
    <material>Gazebo/GreyTransparent</material>
  </gazebo>
  <gazebo reference="left_wheel_big_front">
    <mu1>2.0</mu1>
    <mu2>2.0</mu2>
    <material>Gazebo/GreyTransparent</material>
  </gazebo>
  <gazebo reference="left_wheel_big_back">
    <mu1>2.0</mu1>
    <mu2>2.0</mu2>
    <material>Gazebo/GreyTransparent</material>
  </gazebo>
  <gazebo reference="body_collision">
    <mu1>2.0</mu1>
    <mu2>2.0</mu2>
    <material>Gazebo/GreyTransparent</material>
  </gazebo>
  <!-- 2D LiDAR -->
  <joint name="scan_joint" type="fixed">
    <parent link="base_link"/>
    <child link="base_scan"/>
    <origin rpy="0 0 0" xyz="-0.0 0.0 0.04"/>
  </joint>
  <link name="base_scan">
    <visual>
      <origin rpy="0 0 -1.57" xyz="0 0 0.0"/>
      <geometry>
        <mesh filename="file:///home/emu/ros2_ws/install/cugo_ros2_control/share/cugo_ros2_control/models/cugo/meshes/lds.dae" scale="0.001 0.001 0.001"/>
      </geometry>
      <material name="dark"/>
    </visual>
    <inertial>
      <mass value="0.114"/>
      <origin xyz="0 0 0"/>
      <inertia ixx="0.001" ixy="0.0" ixz="0.0" iyy="0.001" iyz="0.0" izz="0.001"/>
    </inertial>
  </link>
  <gazebo reference="base_scan">
    <material>Gazebo/Grey</material>
    <sensor name="scan" type="ray">
      <pose>0 0 0 0 0 0</pose>
      <visualize>true</visualize>
      <update_rate>30</update_rate>
      <always_on>true</always_on>
      <ray>
        <scan>
          <horizontal>
            <samples>400</samples>
            <resolution>1</resolution>
            <min_angle>-3.141592653589793</min_angle>
            <max_angle>3.141592653589793</max_angle>
          </horizontal>
        </scan>
        <range>
          <min>0.10</min>
          <max>20.0</max>
          <resolution>0.01</resolution>
        </range>
        <noise>
          <type>gaussian</type>
          <mean>0.0</mean>
          <stddev>0.01</stddev>
        </noise>
      </ray>
      <plugin filename="libgazebo_ros_ray_sensor.so" name="gazebo_ros_lidar_controller">
        <ros>
          <remapping>~/out:=scan</remapping>
        </ros>
        <output_type>sensor_msgs/LaserScan</output_type>
        <topicName>/base_scan/scan</topicName>
        <frameName>base_scan</frameName>
      </plugin>
    </sensor>
  </gazebo>
</robot>
